{"uuid": "34ce493c-1323-4620-9347-10a7302f8290", "children": ["eae1d4d8-05eb-4edd-964f-0d1fcbc718c8"], "befores": [{"name": "driver", "status": "broken", "statusDetails": {"message": "urllib3.exceptions.MaxRetryError: HTTPConnectionPool(host='127.0.0.1', port=4723): Max retries exceeded with url: /wd/hub/session (Caused by NewConnectionError('<urllib3.connection.HTTPConnection object at 0x00000194FC20F550>: Failed to establish a new connection: [WinError 10061] No se puede establecer una conexión ya que el equipo de destino denegó expresamente dicha conexión'))\n", "trace": "  File \"E:\\DialerAutomationTest\\venv\\lib\\site-packages\\pluggy\\_callers.py\", line 39, in _multicall\n    res = hook_impl.function(*args)\n  File \"E:\\DialerAutomationTest\\venv\\lib\\site-packages\\_pytest\\fixtures.py\", line 1129, in pytest_fixture_setup\n    result = call_fixture_func(fixturefunc, request, kwargs)\n  File \"E:\\DialerAutomationTest\\venv\\lib\\site-packages\\_pytest\\fixtures.py\", line 901, in call_fixture_func\n    fixture_result = next(generator)\n  File \"E:\\DialerAutomationTest\\DialerAutomationTest\\tests\\conftest.py\", line 34, in driver\n    driver = webdriver.Remote(URL, DESIRED_CAPABILITIES)\n  File \"E:\\DialerAutomationTest\\venv\\lib\\site-packages\\appium\\webdriver\\webdriver.py\", line 230, in __init__\n    super().__init__(\n  File \"E:\\DialerAutomationTest\\venv\\lib\\site-packages\\selenium\\webdriver\\remote\\webdriver.py\", line 286, in __init__\n    self.start_session(capabilities, browser_profile)\n  File \"E:\\DialerAutomationTest\\venv\\lib\\site-packages\\appium\\webdriver\\webdriver.py\", line 320, in start_session\n    response = self.execute(RemoteCommand.NEW_SESSION, w3c_caps)\n  File \"E:\\DialerAutomationTest\\venv\\lib\\site-packages\\selenium\\webdriver\\remote\\webdriver.py\", line 438, in execute\n    response = self.command_executor.execute(driver_command, params)\n  File \"E:\\DialerAutomationTest\\venv\\lib\\site-packages\\selenium\\webdriver\\remote\\remote_connection.py\", line 290, in execute\n    return self._request(command_info[0], url, body=data)\n  File \"E:\\DialerAutomationTest\\venv\\lib\\site-packages\\selenium\\webdriver\\remote\\remote_connection.py\", line 311, in _request\n    response = self._conn.request(method, url, body=body, headers=headers)\n  File \"E:\\DialerAutomationTest\\venv\\lib\\site-packages\\urllib3\\request.py\", line 78, in request\n    return self.request_encode_body(\n  File \"E:\\DialerAutomationTest\\venv\\lib\\site-packages\\urllib3\\request.py\", line 170, in request_encode_body\n    return self.urlopen(method, url, **extra_kw)\n  File \"E:\\DialerAutomationTest\\venv\\lib\\site-packages\\urllib3\\poolmanager.py\", line 376, in urlopen\n    response = conn.urlopen(method, u.request_uri, **kw)\n  File \"E:\\DialerAutomationTest\\venv\\lib\\site-packages\\urllib3\\connectionpool.py\", line 815, in urlopen\n    return self.urlopen(\n  File \"E:\\DialerAutomationTest\\venv\\lib\\site-packages\\urllib3\\connectionpool.py\", line 815, in urlopen\n    return self.urlopen(\n  File \"E:\\DialerAutomationTest\\venv\\lib\\site-packages\\urllib3\\connectionpool.py\", line 815, in urlopen\n    return self.urlopen(\n  File \"E:\\DialerAutomationTest\\venv\\lib\\site-packages\\urllib3\\connectionpool.py\", line 787, in urlopen\n    retries = retries.increment(\n  File \"E:\\DialerAutomationTest\\venv\\lib\\site-packages\\urllib3\\util\\retry.py\", line 592, in increment\n    raise MaxRetryError(_pool, url, error or ResponseError(cause))\n"}, "start": 1677178076050, "stop": 1677178084306}], "start": 1677178076050, "stop": 1677178086142}